# 9.错误处理

rust的错误由2类 ：可恢复 类型 `Result<T、E>` 、 不可恢复 宏 `panic！`

## 9.1使用`panic!`处理不可恢复错误

2种情况引起panic： 代码问题引发panic 或 显式调用`panic!`宏。

默认下，panic后，将打印失败信息、展开（unwinding）、清理堆栈并退出，通过设置可以打印调用堆栈以定位错误原因。

展开（unwinding） ： 当出现panic时，程序默认开始unwinding，Rust会回溯栈并清理它遇到的每一个函数的数据。

展开的背面是 终止（abort） ： 而另一种选择是直接终止（abort），不会清理数据就退出程序。

两种模式切换方法： 在 Cargo.toml 的 `[profile]` 部分增加 `panic = 'abort'`

```rust
[profile.release]
panic = 'abort'
```

手动调用panic!：

```rust
fn main() {
    panic!("crash and burn");
}
```

### 使用panic!的backtrace 回溯

通过例子认识下回溯做了什么：

```rust
fn main() {
    let v = vec![1, 2, 3];

    v[99];
}
```

程序尝试访问超出vector范围的元素，程序必然崩溃，自动调用`panic!` （在c语言中，如果尝试访问超出范围的内存，会由返回的，明显这是不安全的）

通过开启回溯查看更多信息 ： `RUST_BACKTRACE=1 cargo run`，返回信息如下：

```rust
$ RUST_BACKTRACE=1 cargo run
thread 'main' panicked at src/main.rs:4:6:
index out of bounds: the len is 3 but the index is 99
stack backtrace:
   0: rust_begin_unwind
             at /rustc/4d91de4e48198da2e33413efdcd9cd2cc0c46688/library/std/src/panicking.rs:692:5
   1: core::panicking::panic_fmt
             at /rustc/4d91de4e48198da2e33413efdcd9cd2cc0c46688/library/core/src/panicking.rs:75:14
   2: core::panicking::panic_bounds_check
             at /rustc/4d91de4e48198da2e33413efdcd9cd2cc0c46688/library/core/src/panicking.rs:273:5
   3: <usize as core::slice::index::SliceIndex<[T]>>::index
             at file:///home/.rustup/toolchains/1.85/lib/rustlib/src/rust/library/core/src/slice/index.rs:274:10
   4: core::slice::index::<impl core::ops::index::Index<I> for [T]>::index
             at file:///home/.rustup/toolchains/1.85/lib/rustlib/src/rust/library/core/src/slice/index.rs:16:9
   5: <alloc::vec::Vec<T,A> as core::ops::index::Index<I>>::index
             at file:///home/.rustup/toolchains/1.85/lib/rustlib/src/rust/library/alloc/src/vec/mod.rs:3361:9
   6: panic::main
             at ./src/main.rs:4:6
   7: core::ops::function::FnOnce::call_once
             at file:///home/.rustup/toolchains/1.85/lib/rustlib/src/rust/library/core/src/ops/function.rs:250:5
note: Some details are omitted, run with `RUST_BACKTRACE=full` for a verbose backtrace.
```

回溯backtrace的第6行指向了项目中造成问题的行：`./src/main.rs:4:6`表示第4行，如果要调查问题就应该从第一个开始一知道我们自己编写的文件那一行。

## 9.2用`Result`处理可恢复错误

第二章由提过Result枚举，定义如下2个变体：

```rust
enum Result<T, E> {
    Ok(T),
    Err(E),
}
```

T和E都是泛型类型参数，T 代表成功时返回的Ok变体中的数据的类型，E代表失败时返回的Err变体中的错误的类型。

现在调用一个能返回Result类型的函数。

```rust
use std::fs::File;

fn main() {
    let greeting_file_result = File::open("hello.txt");
}
```

`File::open`返回一个`Result<T, E>` 。泛型参数 T 会被 `File::open` 的实现放入成功返回值的类型 `std::fs::File`。 错误返回值则使用的 E 的类型是 `std::io::Error` 。 当 `File::open` 成功时，`greeting_file_result` 变量将会是一个包含文件句柄的 Ok 实例。当失败时，`greeting_file_result` 变量将会是一个包含了更多关于发生了何种错误的信息的 Err 实例。

修改上面代码，要求对`File::open`返回值，即`greeting_file_result`添加不同的处理逻辑：

```rust
use std::fs::File;

fn main() {
    let greeting_file_result = File::open("hello.txt");

    let greeting_file = match greeting_file_result {
        Ok(file) => file,
        Err(error) => panic!("Problem opening the file: {error:?}"),
    };
}
```

现在无论`File::open` 是因为什么原因失败都会 panic!

继续添加要求 ： 当遇到因为文件不存在而失败的情况，处理：创建新文件。而其他错误依然执行panic!

```rust
use std::fs::File;
use std::io::ErrorKind;

fn main() {
    let greeting_file_result = File::open("hello.txt");

    let greeting_file = match greeting_file_result {
        Ok(file) => file,
        Err(error) => match error.kind() {
            ErrorKind::NotFound => match File::create("hello.txt") {
                Ok(fc) => fc,
                Err(e) => panic!("Problem creating the file: {e:?}"),
            },
            _ => {
                panic!("Problem opening the file: {error:?}");
            }
        },
    };
}
```

说明：Err 变体中的值类型 io::Error 是标准库提供的结构提，体内由一个返回`io::ErrorKind` 值的 `kind` 方法可供调用 ， `io::ErrorKind` 是一个标准库提供的枚举，其中 变体是 ErrorKind::NotFound，代表尝试打开的文件并不存在， 通过 File::create 尝试创建该文件 但创建过程也可能失败，所以继续使用match写明如果失败后的处理。

### 失败时 panic 的快捷方式：unwrap 和 expect
